Workbook

Sheet Raw_Data
A1: US CPI Monthly Data (All Urban Consumers, CPIAUCNS) — Source: FRED, Jan 2020 – Dec 2024
A2: Year | B2: Month | C2: t | D2: CPI (Monthly Avg) | E2: Month Name | F2: Notes
A3: 2020 | B3: 1 | C3: 1 | D3: 257.971 | E3: Jan | F3: Training data
A4: 2020 | B4: 2 | C4: 2 | D4: 258.678 | E4: Feb | F4: Training data
A5: 2020 | B5: 3 | C5: 3 | D5: 258.115 | E5: Mar | F5: Training data
A6: 2020 | B6: 4 | C6: 4 | D6: 256.389 | E6: Apr | F6: Training data
A7: 2020 | B7: 5 | C7: 5 | D7: 256.394 | E7: May | F7: Training data
A8: 2020 | B8: 6 | C8: 6 | D8: 257.797 | E8: Jun | F8: Training data
A9: 2020 | B9: 7 | C9: 7 | D9: 259.101 | E9: Jul | F9: Training data
A10: 2020 | B10: 8 | C10: 8 | D10: 259.918 | E10: Aug | F10: Training data
A11: 2020 | B11: 9 | C11: 9 | D11: 260.28 | E11: Sep | F11: Training data
A12: 2020 | B12: 10 | C12: 10 | D12: 260.388 | E12: Oct | F12: Training data
A13: 2020 | B13: 11 | C13: 11 | D13: 260.229 | E13: Nov | F13: Training data
A14: 2020 | B14: 12 | C14: 12 | D14: 260.474 | E14: Dec | F14: Training data
... A62: 2024 | B62: 12 | C62: 60 | D62: 315.605 | E62: Dec | F62: Training data
A64: Forecast (2025)
A65: 2025 | B65: 1 | C65: 61 | E65: Jan | F65: Forecast period
A66: 2025 | B66: 2 | C66: 62 | E66: Feb | F66: Forecast period
A67: 2025 | B67: 3 | C67: 63 | E67: Mar | F67: Forecast period
A68: 2025 | B68: 4 | C68: 64 | E68: Apr | F68: Forecast period
A69: 2025 | B69: 5 | C69: 65 | E69: May | F69: Forecast period
A70: 2025 | B70: 6 | C70: 66 | E70: Jun | F70: Forecast period
A71: 2025 | B71: 7 | C71: 67 | E71: Jul | F71: Forecast period
A72: 2025 | B72: 8 | C72: 68 | E72: Aug | F72: Forecast period
A73: 2025 | B73: 9 | C73: 69 | E73: Sep | F73: Forecast period
A74: 2025 | B74: 10 | C74: 70 | E74: Oct | F74: Forecast period
A75: 2025 | B75: 11 | C75: 71 | E75: Nov | F75: Forecast period
A76: 2025 | B76: 12 | C76: 72 | E76: Dec | F76: Forecast period

Sheet MD
A1: Year | B1: t | C1: Y | D1: CMA | E1: S*I | F1: SR_bar | G1: S | H1: DY | I1: DY^ | J1: Y^ | K1: C*I | L1: C | M1: I | N1: e^2 | O1: abs(e/Y) | P1: SUMMARY OUTPUT
C2: T*C*S*I | D2: T*C | E2: Y/CMA | G2: SR_bar*s/Sum(SR) | H2: Y/S | I2: T | J2: T*S | K2: Y/Y^ | L2: Third(C*I) | M2: (C*I)/C | N2: (Y-Y^)2
A3: 1 | B3: 1 | C3: 257.971 | F3: =AVERAGE(E15,E27,E39,E51) -> 0.99434891 | G3: =F3*12/SUM(F$3:F$14) -> 0.99433039 | H3: =C3/G3 -> 259.44193 | I3: =(Q$17+Q$18*B3) -> 253.1428 | J3: =(Q$17+Q$18*B3)*G3 -> 251.70758 | K3: =C3/J3 -> 1.0248837 | N3: =(C3-J3)^2 -> 39.230482 | O3: =ABS(C3-J3)/C3 -> 0.024279567 | P3: Regression Statistics
B4: 2 | C4: 258.678 | F4: =AVERAGE(E16,E28,E40,E52) -> 0.99688249 | G4: =F4*12/SUM(F$3:F$14) -> 0.99686392 | H4: =C4/G4 -> 259.49179 | I4: =(Q$17+Q$18*B4) -> 254.33011 | J4: =(Q$17+Q$18*B4)*G4 -> 253.53251 | K4: =C4/J4 -> 1.0202952 | L4: =AVERAGE(K3:K5) -> 1.0183201 | M4: =K4/L4 -> 1.0019396 | N4: =(C4-J4)^2 -> 26.476081 | O4: =ABS(C4-J4)/C4 -> 0.019891492 | P4: Multiple R | Q4: 0.9844862
B5: 3 | C5: 258.115 | F5: =AVERAGE(E17,E29,E41,E53) -> 1.0003996 | G5: =F5*12/SUM(F$3:F$14) -> 1.000381 | H5: =C5/G5 -> 258.0167 | I5: =(Q$17+Q$18*B5) -> 255.51742 | J5: =(Q$17+Q$18*B5)*G5 -> 255.61477 | K5: =C5/J5 -> 1.0097812 | L5: =AVERAGE(K4:K6) -> 1.008934 | M5: =K5/L5 -> 1.0008397 | N5: =(C5-J5)^2 -> 6.2511425 | O5: =ABS(C5-J5)/C5 -> 0.0096864905 | P5: R Square | Q5: 0.96921308
B6: 4 | C6: 256.389 | F6: =AVERAGE(E18,E30,E42,E54) -> 1.0020698 | G6: =F6*12/SUM(F$3:F$14) -> 1.0020511 | H6: =C6/G6 -> 255.86419 | I6: =(Q$17+Q$18*B6) -> 256.70473 | J6: =(Q$17+Q$18*B6)*G6 -> 257.23127 | K6: =C6/J6 -> 0.99672563 | L6: =AVERAGE(K5:K7) -> 0.99896654 | M6: =K6/L6 -> 0.99775677 | N6: =(C6-J6)^2 -> 0.70941794 | O6: =ABS(C6-J6)/C6 -> 0.0032851235 | P6: Adjusted R Square | Q6: 0.96868227
B7: 5 | C7: 256.394 | F7: =AVERAGE(E19,E31,E43,E55) -> 1.003854 | G7: =F7*12/SUM(F$3:F$14) -> 1.0038353 | H7: =C7/G7 -> 255.41441 | I7: =(Q$17+Q$18*B7) -> 257.89204 | J7: =(Q$17+Q$18*B7)*G7 -> 258.88113 | K7: =C7/J7 -> 0.99039276 | L7: =AVERAGE(K6:K8) -> 0.99191721 | M7: =K7/L7 -> 0.99846313 | N7: =(C7-J7)^2 -> 6.1858275 | O7: =ABS(C7-J7)/C7 -> 0.0097004313 | P7: Standard Error | Q7: 3.7273509
B8: 6 | C8: 257.797 | F8: =AVERAGE(E20,E32,E44,E56) -> 1.0065096 | G8: =F8*12/SUM(F$3:F$14) -> 1.0064909 | H8: =C8/G8 -> 256.13446 | I8: =(Q$17+Q$18*B8) -> 259.07936 | J8: =(Q$17+Q$18*B8)*G8 -> 260.76101 | K8: =C8/J8 -> 0.98863322 | L8: =AVERAGE(K7:K9) -> 0.99013547 | M8: =K8/L8 -> 0.99848278 | N8: =(C8-J8)^2 -> 8.7853708 | O8: =ABS(C8-J8)/C8 -> 0.011497467 | P8: Observations | Q8: 60
B9: 7 | C9: 259.101 | D9: =(0.5*C3+C4+C5+C6+C7+C8+C9+C10+C11+C12+C13+C14+0.5*C15)/12 -> 258.96163 | E9: =C9/D9 -> 1.0005382 | F9: =AVERAGE(E9,E21,E33,E45) -> 1.0041955 | G9: =F9*12/SUM(F$3:F$14) -> 1.0041768 | H9: =C9/G9 -> 258.02328 | I9: =(Q$17+Q$18*B9) -> 260.26667 | J9: =(Q$17+Q$18*B9)*G9 -> 261.35376 | K9: =C9/J9 -> 0.99138043 | L9: =AVERAGE(K8:K10) -> 0.99047771 | M9: =K9/L9 -> 1.0009114 | N9: =(C9-J9)^2 -> 5.0749122 | O9: =ABS(C9-J9)/C9 -> 0.0086945113
B10: 8 | C10: 259.918 | D10: =(0.5*C4+C5+C6+C7+C8+C9+C10+C11+C12+C13+C14+C15+0.5*C16)/12 -> 259.29275 | E10: =C10/D10 -> 1.0024114 | F10: =AVERAGE(E10,E22,E34,E46) -> 1.0027479 | G10: =F10*12/SUM(F$3:F$14) -> 1.0027292 | H10: =C10/G10 -> 259.21057 | I10: =(Q$17+Q$18*B10) -> 261.45398 | J10: =(Q$17+Q$18*B10)*G10 -> 262.16753 | K10: =C10/J10 -> 0.99141948 | L10: =AVERAGE(K9:K11) -> 0.99092883 | M10: =K10/L10 -> 1.0004951 | N10: =(C10-J10)^2 -> 5.060406 | O10: =ABS(C10-J10)/C10 -> 0.0086547859 | P10: ANOVA
B11: 9 | C11: 260.28 | D11: =(0.5*C5+C6+C7+C8+C9+C10+C11+C12+C13+C14+C15+C16+0.5*C17)/12 -> 259.75517 | E11: =C11/D11 -> 1.0020205 | F11: =AVERAGE(E11,E23,E35,E47) -> 1.0010519 | G11: =F11*12/SUM(F$3:F$14) -> 1.0010332 | H11: =C11/G11 -> 260.01135 | I11: =(Q$17+Q$18*B11) -> 262.64129 | J11: =(Q$17+Q$18*B11)*G11 -> 262.91266 | K11: =C11/J11 -> 0.98998657 | L11: =AVERAGE(K10:K12) -> 0.98944489 | M11: =K11/L11 -> 1.0005475 | N11: =(C11-J11)^2 -> 6.9308824 | O11: =ABS(C11-J11)/C11 -> 0.010114711 | Q11: df | R11: SS | S11: MS | T11: F | U11: Significance F
B12: 10 | C12: 260.388 | D12: =(0.5*C6+C7+C8+C9+C10+C11+C12+C13+C14+C15+C16+C17+0.5*C18)/12 -> 260.48129 | E12: =C12/D12 -> 0.99964185 | F12: =AVERAGE(E12,E24,E36,E48) -> 1.0000493 | G12: =F12*12/SUM(F$3:F$14) -> 1.0000307 | H12: =C12/G12 -> 260.38 | I12: =(Q$17+Q$18*B12) -> 263.8286 | J12: =(Q$17+Q$18*B12)*G12 -> 263.83671 | K12: =C12/J12 -> 0.98692862 | L12: =AVERAGE(K11:K13) -> 0.98755505 | M12: =K12/L12 -> 0.99936568 | N12: =(C12-J12)^2 -> 11.893598 | O12: =ABS(C12-J12)/C12 -> 0.013244503 | P12: Regression | Q12: 1 | R12: 25367.731 | S12: 25367.731 | T12: 1825.9171 | U12: 1.5400501e-45
B13: 11 | C13: 260.229 | D13: =(0.5*C7+C8+C9+C10+C11+C12+C13+C14+C15+C16+C17+C18+0.5*C19)/12 -> 261.45904 | E13: =C13/D13 -> 0.99529547 | F13: =AVERAGE(E13,E25,E37,E49) -> 0.99615072 | G13: =F13*12/SUM(F$3:F$14) -> 0.99613217 | H13: =C13/G13 -> 261.23943 | I13: =(Q$17+Q$18*B13) -> 265.01592 | J13: =(Q$17+Q$18*B13)*G13 -> 263.99088 | K13: =C13/J13 -> 0.98574996 | L13: =AVERAGE(K12:K14) -> 0.98636732 | M13: =K13/L13 -> 0.99937411 | N13: =(C13-J13)^2 -> 14.151745 | O13: =ABS(C13-J13)/C13 -> 0.014456039 | P13: Residual | Q13: 58 | R13: 805.80239 | S13: 13.893145
B14: 12 | C14: 260.474 | D14: =(0.5*C8+C9+C10+C11+C12+C13+C14+C15+C16+C17+C18+C19+0.5*C20)/12 -> 262.57154 | E14: =C14/D14 -> 0.99201154 | F14: =AVERAGE(E14,E26,E38,E50) -> 0.99196373 | G14: =F14*12/SUM(F$3:F$14) -> 0.99194526 | H14: =C14/G14 -> 262.58909 | I14: =(Q$17+Q$18*B14) -> 266.20323 | J14: =(Q$17+Q$18*B14)*G14 -> 264.05903 | K14: =C14/J14 -> 0.98642337 | L14: =AVERAGE(K13:K15) -> 0.98534278 | M14: =K14/L14 -> 1.0010967 | N14: =(C14-J14)^2 -> 12.852444 | O14: =ABS(C14-J14)/C14 -> 0.013763487 | P14: Total | Q14: 59 | R14: 26173.533
A15: 2 | B15: 13 | C15: 261.582 | D15: =(0.5*C9+C10+C11+C12+C13+C14+C15+C16+C17+C18+C19+C20+0.5*C21)/12 -> 263.72992 | E15: =C15/D15 -> 0.99185562 | F15: =SUM(F3:F14) -> 12.000223 | G15: =G3 -> 0.99433039 | H15: =C15/G15 -> 263.07352 | I15: =(Q$17+Q$18*B15) -> 267.39054 | J15: =(Q$17+Q$18*B15)*G15 -> 265.87454 | K15: =C15/J15 -> 0.98385501 | L15: =AVERAGE(K14:K16) -> 0.98421439 | M15: =K15/L15 -> 0.99963485 | N15: =(C15-J15)^2 -> 18.425914 | O15: =ABS(C15-J15)/C15 -> 0.016409927
B16: 14 | C16: 263.014 | D16: =(0.5*C10+C11+C12+C13+C14+C15+C16+C17+C18+C19+C20+C21+0.5*C22)/12 -> 264.87788 | E16: =C16/D16 -> 0.99296327 | G16: =G4 -> 0.99686392 | H16: =C16/G16 -> 263.84143 | I16: =(Q$17+Q$18*B16) -> 268.57785 | J16: =(Q$17+Q$18*B16)*G16 -> 267.73557 | K16: =C16/J16 -> 0.9823648 | L16: =AVERAGE(K15:K17) -> 0.98257526 | M16: =K16/L16 -> 0.9997858 | N16: =(C16-J16)^2 -> 22.293237 | O16: =ABS(C16-J16)/C16 -> 0.017951787 | Q16: Coefficients | R16: Standard Error | S16: t Stat | T16: P-value | U16: Lower 95% | V16: Upper 95% | W16: Lower 95.0% | X16: Upper 95.0%
B17: 15 | C17: 264.877 | D17: =(0.5*C11+C12+C13+C14+C15+C16+C17+C18+C19+C20+C21+C22+0.5*C23)/12 -> 266.03117 | E17: =C17/D17 -> 0.99566154 | G17: =G5 -> 1.000381 | H17: =C17/G17 -> 264.77612 | I17: =(Q$17+Q$18*B17) -> 269.76516 | J17: =(Q$17+Q$18*B17)*G17 -> 269.86794 | K17: =C17/J17 -> 0.98150597 | L17: =AVERAGE(K16:K18) -> 0.98248841 | M17: =K17/L17 -> 0.99900005 | N17: =(C17-J17)^2 -> 24.909529 | O17: =ABS(C17-J17)/C17 -> 0.018842499 | P17: Intercept | Q17: 251.95548 | R17: 0.97455495 | S17: 258.53389 | T17: 1.6634507e-90 | U17: 250.0047 | V17: 253.90627 | W17: 250.0047 | X17: 253.90627
B18: 16 | C18: 267.054 | D18: =(0.5*C12+C13+C14+C15+C16+C17+C18+C19+C20+C21+C22+C23+0.5*C24)/12 -> 267.29079 | E18: =C18/D18 -> 0.9991141 | G18: =G6 -> 1.0020511 | H18: =C18/G18 -> 266.50736 | I18: =(Q$17+Q$18*B18) -> 270.95248 | J18: =(Q$17+Q$18*B18)*G18 -> 271.50824 | K18: =C18/J18 -> 0.98359446 | L18: =AVERAGE(K17:K19) -> 0.98350009 | M18: =K18/L18 -> 1.000096 | N18: =(C18-J18)^2 -> 19.840241 | O18: =ABS(C18-J18)/C18 -> 0.016679168 | P18: X Variable 1 | Q18: 1.1873121 | R18: 0.027785893 | S18: 42.730751 | T18: 1.5400501e-45 | U18: 1.1316926 | V18: 1.2429316 | W18: 1.1316926 | X18: 1.2429316
B19: 17 | C19: 269.195 | D19: =(0.5*C13+C14+C15+C16+C17+C18+C19+C20+C21+C22+C23+C24+0.5*C25)/12 -> 268.70413 | E19: =C19/D19 -> 1.0018268 | G19: =G7 -> 1.0038353 | H19: =C19/G19 -> 268.16651 | I19: =(Q$17+Q$18*B19) -> 272.13979 | J19: =(Q$17+Q$18*B19)*G19 -> 273.18352 | K19: =C19/J19 -> 0.98539985 | L19: =AVERAGE(K18:K20) -> 0.98553873 | M19: =K19/L19 -> 0.99985908 | N19: =(C19-J19)^2 -> 15.908302 | O19: =ABS(C19-J19)/C19 -> 0.014816476
B20: 18 | C20: 271.696 | D20: =(0.5*C14+C15+C16+C17+C18+C19+C20+C21+C22+C23+C24+C25+0.5*C26)/12 -> 270.20608 | E20: =C20/D20 -> 1.005514 | G20: =G8 -> 1.0064909 | H20: =C20/G20 -> 269.94382 | I20: =(Q$17+Q$18*B20) -> 273.3271 | J20: =(Q$17+Q$18*B20)*G20 -> 275.10124 | K20: =C20/J20 -> 0.98762187 | L20: =AVERAGE(K19:K21) -> 0.98779313 | M20: =K20/L20 -> 0.99982662 | N20: =(C20-J20)^2 -> 11.595646 | O20: =ABS(C20-J20)/C20 -> 0.012533265
B21: 19 | C21: 273.003 | D21: =(0.5*C15+C16+C17+C18+C19+C20+C21+C22+C23+C24+C25+C26+0.5*C27)/12 -> 271.785 | E21: =C21/D21 -> 1.0044815 | G21: =G9 -> 1.0041768 | H21: =C21/G21 -> 271.86746 | I21: =(Q$17+Q$18*B21) -> 274.51441 | J21: =(Q$17+Q$18*B21)*G21 -> 275.66101 | K21: =C21/J21 -> 0.99035768 | L21: =AVERAGE(K20:K22) -> 0.98917867 | M21: =K21/L21 -> 1.0011919 | N21: =(C21-J21)^2 -> 7.0650265 | O21: =ABS(C21-J21)/C21 -> 0.0097361998
B22: 20 | C22: 273.567 | D22: =(0.5*C16+C17+C18+C19+C20+C21+C22+C23+C24+C25+C26+C27+0.5*C28)/12 -> 273.46283 | E22: =C22/D22 -> 1.0003809 | G22: =G10 -> 1.0027292 | H22: =C22/G22 -> 272.82242 | I22: =(Q$17+Q$18*B22) -> 275.70173 | J22: =(Q$17+Q$18*B22)*G22 -> 276.45416 | K22: =C22/J22 -> 0.98955645 | L22: =AVERAGE(K21:K23) -> 0.98985909 | M22: =K22/L22 -> 0.99969426 | N22: =(C22-J22)^2 -> 8.3357166 | O22: =ABS(C22-J22)/C22 -> 0.010553773
B23: 21 | C23: 274.31 | D23: =(0.5*C17+C18+C19+C20+C21+C22+C23+C24+C25+C26+C27+C28+0.5*C29)/12 -> 275.26821 | E23: =C23/D23 -> 0.996519 | G23: =G11 -> 1.0010332 | H23: =C23/G23 -> 274.02687 | I23: =(Q$17+Q$18*B23) -> 276.88904 | J23: =(Q$17+Q$18*B23)*G23 -> 277.17512 | K23: =C23/J23 -> 0.98966313 | L23: =AVERAGE(K22:K24) -> 0.9912801 | M23: =K23/L23 -> 0.9983688 | N23: =(C23-J23)^2 -> 8.2089282 | O23: =ABS(C23-J23)/C23 -> 0.010444835
B24: 22 | C24: 276.589 | D24: =(0.5*C18+C19+C20+C21+C22+C23+C24+C25+C26+C27+C28+C29+0.5*C30)/12 -> 277.12996 | E24: =C24/D24 -> 0.998048 | G24: =G12 -> 1.0000307 | H24: =C24/G24 -> 276.5805 | I24: =(Q$17+Q$18*B24) -> 278.07635 | J24: =(Q$17+Q$18*B24)*G24 -> 278.08489 | K24: =C24/J24 -> 0.99462074 | L24: =AVERAGE(K23:K25) -> 0.99447908 | M24: =K24/L24 -> 1.0001424 | N24: =(C24-J24)^2 -> 2.2376934 | O24: =ABS(C24-J24)/C24 -> 0.0054083574
B25: 23 | C25: 277.948 | D25: =(0.5*C19+C20+C21+C22+C23+C24+C25+C26+C27+C28+C29+C30+0.5*C31)/12 -> 279.01146 | E25: =C25/D25 -> 0.99618848 | G25: =G13 -> 0.99613217 | H25: =C25/G25 -> 279.02723 | I25: =(Q$17+Q$18*B25) -> 279.26366 | J25: =(Q$17+Q$18*B25)*G25 -> 278.18352 | K25: =C25/J25 -> 0.99915337 | L25: =AVERAGE(K24:K26) -> 0.9986556 | M25: =K25/L25 -> 1.0004984 | N25: =(C25-J25)^2 -> 0.055468523 | O25: =ABS(C25-J25)/C25 -> 0.00084734398
B26: 24 | C26: 278.802 | D26: =(0.5*C20+C21+C22+C23+C24+C25+C26+C27+C28+C29+C30+C31+0.5*C32)/12 -> 280.99962 | E26: =C26/D26 -> 0.99217926 | G26: =G14 -> 0.99194526 | H26: =C26/G26 -> 281.06591 | I26: =(Q$17+Q$18*B26) -> 280.45097 | J26: =(Q$17+Q$18*B26)*G26 -> 278.19201 | K26: =C26/J26 -> 1.0021927 | L26: =AVERAGE(K25:K27) -> 1.0017657 | M26: =K26/L26 -> 1.0004262 | N26: =(C26-J26)^2 -> 0.37208358 | O26: =ABS(C26-J26)/C26 -> 0.0021878844
A27: 3 | B27: 25 | C27: 281.148 | D27: =(0.5*C21+C22+C23+C24+C25+C26+C27+C28+C29+C30+C31+C32+0.5*C33)/12 -> 282.99496 | E27: =C27/D27 -> 0.99347353 | G27: =G3 -> 0.99433039 | H27: =C27/G27 -> 282.75109 | I27: =(Q$17+Q$18*B27) -> 281.63829 | J27: =(Q$17+Q$18*B27)*G27 -> 280.04151 | K27: =C27/J27 -> 1.0039512 | L27: =AVERAGE(K26:K28) -> 1.0041493 | M27: =K27/L27 -> 0.99980268 | N27: =(C27-J27)^2 -> 1.2243259 | O27: =ABS(C27-J27)/C27 -> 0.0039356233
B28: 26 | C28: 283.716 | D28: =(0.5*C22+C23+C24+C25+C26+C27+C28+C29+C30+C31+C32+C33+0.5*C34)/12 -> 284.9065 | E28: =C28/D28 -> 0.99582144 | G28: =G4 -> 0.99686392 | H28: =C28/G28 -> 284.60855 | I28: =(Q$17+Q$18*B28) -> 282.8256 | J28: =(Q$17+Q$18*B28)*G28 -> 281.93863 | K28: =C28/J28 -> 1.0063041 | L28: =AVERAGE(K27:K29) -> 1.0073872 | M28: =K28/L28 -> 0.99892478 | N28: =(C28-J28)^2 -> 3.1590291 | O28: =ABS(C28-J28)/C28 -> 0.0062645947
B29: 27 | C29: 287.504 | D29: =(0.5*C23+C24+C25+C26+C27+C28+C29+C30+C31+C32+C33+C34+0.5*C35)/12 -> 286.78575 | E29: =C29/D29 -> 1.0025045 | G29: =G5 -> 1.000381 | H29: =C29/G29 -> 287.3945 | I29: =(Q$17+Q$18*B29) -> 284.01291 | J29: =(Q$17+Q$18*B29)*G29 -> 284.12112 | K29: =C29/J29 -> 1.0119065 | L29: =AVERAGE(K28:K30) -> 1.009947 | M29: =K29/L29 -> 1.0019402 | N29: =(C29-J29)^2 -> 11.443891 | O29: =ABS(C29-J29)/C29 -> 0.011766383
B30: 28 | C30: 289.109 | D30: =(0.5*C24+C25+C26+C27+C28+C29+C30+C31+C32+C33+C34+C35+0.5*C36)/12 -> 288.61579 | E30: =C30/D30 -> 1.0017089 | G30: =G6 -> 1.0020511 | H30: =C30/G30 -> 288.51721 | I30: =(Q$17+Q$18*B30) -> 285.20022 | J30: =(Q$17+Q$18*B30)*G30 -> 285.78521 | K30: =C30/J30 -> 1.0116304 | L30: =AVERAGE(K29:K31) -> 1.0134228 | M30: =K30/L30 -> 0.99823132 | N30: =(C30-J30)^2 -> 11.047597 | O30: =ABS(C30-J30)/C30 -> 0.011496676
B31: 29 | C31: 292.296 | D31: =(0.5*C25+C26+C27+C28+C29+C30+C31+C32+C33+C34+C35+C36+0.5*C37)/12 -> 290.33188 | E31: =C31/D31 -> 1.0067651 | G31: =G7 -> 1.0038353 | H31: =C31/G31 -> 291.17925 | I31: =(Q$17+Q$18*B31) -> 286.38753 | J31: =(Q$17+Q$18*B31)*G31 -> 287.48591 | K31: =C31/J31 -> 1.0167316 | L31: =AVERAGE(K30:K32) -> 1.0173652 | M31: =K31/L31 -> 0.99937714 | N31: =(C31-J31)^2 -> 23.136963 | O31: =ABS(C31-J31)/C31 -> 0.016456228
B32: 30 | C32: 296.311 | D32: =(0.5*C26+C27+C28+C29+C30+C31+C32+C33+C34+C35+C36+C37+0.5*C38)/12 -> 291.90512 | E32: =C32/D32 -> 1.0150935 | G32: =G8 -> 1.0064909 | H32: =C32/G32 -> 294.40008 | I32: =(Q$17+Q$18*B32) -> 287.57485 | J32: =(Q$17+Q$18*B32)*G32 -> 289.44146 | K32: =C32/J32 -> 1.0237338 | L32: =AVERAGE(K31:K33) -> 1.0207395 | M32: =K32/L32 -> 1.0029334 | N32: =(C32-J32)^2 -> 47.190532 | O32: =ABS(C32-J32)/C32 -> 0.023183535
B33: 31 | C33: 296.276 | D33: =(0.5*C27+C28+C29+C30+C31+C32+C33+C34+C35+C36+C37+C38+0.5*C39)/12 -> 293.40583 | E33: =C33/D33 -> 1.0097822 | G33: =G9 -> 1.0041768 | H33: =C33/G33 -> 295.04365 | I33: =(Q$17+Q$18*B33) -> 288.76216 | J33: =(Q$17+Q$18*B33)*G33 -> 289.96827 | K33: =C33/J33 -> 1.0217532 | L33: =AVERAGE(K32:K34) -> 1.021388 | M33: =K33/L33 -> 1.0003575 | N33: =(C33-J33)^2 -> 39.787496 | O33: =ABS(C33-J33)/C33 -> 0.021290057
B34: 32 | C34: 296.171 | D34: =(0.5*C28+C29+C30+C31+C32+C33+C34+C35+C36+C37+C38+C39+0.5*C40)/12 -> 294.87025 | E34: =C34/D34 -> 1.0044113 | G34: =G10 -> 1.0027292 | H34: =C34/G34 -> 295.3649 | I34: =(Q$17+Q$18*B34) -> 289.94947 | J34: =(Q$17+Q$18*B34)*G34 -> 290.74079 | K34: =C34/J34 -> 1.0186771 | L34: =AVERAGE(K33:K35) -> 1.0196192 | M34: =K34/L34 -> 0.99907605 | N34: =(C34-J34)^2 -> 29.487142 | O34: =ABS(C34-J34)/C34 -> 0.0183347
B35: 33 | C35: 296.808 | D35: =(0.5*C29+C30+C31+C32+C33+C34+C35+C36+C37+C38+C39+C40+0.5*C41)/12 -> 296.18092 | E35: =C35/D35 -> 1.0021172 | G35: =G11 -> 1.0010332 | H35: =C35/G35 -> 296.50165 | I35: =(Q$17+Q$18*B35) -> 291.13678 | J35: =(Q$17+Q$18*B35)*G35 -> 291.43759 | K35: =C35/J35 -> 1.0184273 | L35: =AVERAGE(K34:K36) -> 1.0188436 | M35: =K35/L35 -> 0.99959145 | N35: =(C35-J35)^2 -> 28.841319 | O35: =ABS(C35-J35)/C35 -> 0.018093891
B36: 34 | C36: 298.012 | D36: =(0.5*C30+C31+C32+C33+C34+C35+C36+C37+C38+C39+C40+C41+0.5*C42)/12 -> 297.372 | E36: =C36/D36 -> 1.0021522 | G36: =G12 -> 1.0000307 | H36: =C36/G36 -> 298.00284 | I36: =(Q$17+Q$18*B36) -> 292.32409 | J36: =(Q$17+Q$18*B36)*G36 -> 292.33307 | K36: =C36/J36 -> 1.0194262 | L36: =AVERAGE(K35:K37) -> 1.0187 | M36: =K36/L36 -> 1.0007129 | N36: =(C36-J36)^2 -> 32.250192 | O36: =ABS(C36-J36)/C36 -> 0.019056029
B37: 35 | C37: 297.711 | D37: =(0.5*C31+C32+C33+C34+C35+C36+C37+C38+C39+C40+C41+C42+0.5*C43)/12 -> 298.45887 | E37: =C37/D37 -> 0.99749421 | G37: =G13 -> 0.99613217 | H37: =C37/G37 -> 298.86697 | I37: =(Q$17+Q$18*B37) -> 293.51141 | J37: =(Q$17+Q$18*B37)*G37 -> 292.37615 | K37: =C37/J37 -> 1.0182465 | L37: =AVERAGE(K36:K38) -> 1.0176569 | M37: =K37/L37 -> 1.0005794 | N37: =(C37-J37)^2 -> 28.460576 | O37: =ABS(C37-J37)/C37 -> 0.017919544
B38: 36 | C38: 296.797 | D38: =(0.5*C32+C33+C34+C35+C36+C37+C38+C39+C40+C41+C42+C43+0.5*C44)/12 -> 299.31842 | E38: =C38/D38 -> 0.99157614 | G38: =G14 -> 0.99194526 | H38: =C38/G38 -> 299.20704 | I38: =(Q$17+Q$18*B38) -> 294.69872 | J38: =(Q$17+Q$18*B38)*G38 -> 292.325 | K38: =C38/J38 -> 1.0152981 | L38: =AVERAGE(K37:K39) -> 1.0168029 | M38: =K38/L38 -> 0.99852007 | N38: =(C38-J38)^2 -> 19.998816 | O38: =ABS(C38-J38)/C38 -> 0.01506755
A39: 4 | B39: 37 | C39: 299.17 | D39: =(0.5*C33+C34+C35+C36+C37+C38+C39+C40+C41+C42+C43+C44+0.5*C45)/12 -> 300.07729 | E39: =C39/D39 -> 0.99697647 | G39: =G3 -> 0.99433039 | H39: =C39/G39 -> 300.87585 | I39: =(Q$17+Q$18*B39) -> 295.88603 | J39: =(Q$17+Q$18*B39)*G39 -> 294.20847 | K39: =C39/J39 -> 1.016864 | L39: =AVERAGE(K38:K40) -> 1.016009 | M39: =K39/L39 -> 1.0008415 | N39: =(C39-J39)^2 -> 24.616749 | O39: =ABS(C39-J39)/C39 -> 0.016584306
B40: 38 | C40: 300.84 | D40: =(0.5*C34+C35+C36+C37+C38+C39+C40+C41+C42+C43+C44+C45+0.5*C46)/12 -> 300.92187 | E40: =C40/D40 -> 0.99972792 | G40: =G4 -> 0.99686392 | H40: =C40/G40 -> 301.78643 | I40: =(Q$17+Q$18*B40) -> 297.07334 | J40: =(Q$17+Q$18*B40)*G40 -> 296.1417 | K40: =C40/J40 -> 1.0158651 | L40: =AVERAGE(K39:K41) -> 1.014777 | M40: =K40/L40 -> 1.0010722 | N40: =(C40-J40)^2 -> 22.074051 | O40: =ABS(C40-J40)/C40 -> 0.015617281
...

Sheet MDF
A1: t | B1: S | C1: T | D1: Y^ | E1: Y^L | F1: Y^U | G1: sT
E2: Y^-(Za/2*sT) | F2: Y^+(Za/2*sT)
A3: =MD!B62 -> 60 | B3: =MD!G62 -> 0.99194526 | C3: 324.38152 | D3: =B3*C3 -> 321.76871 | E3: =D3-1.96*G3 -> 314.21752 | F3: =D3+1.96*G3 -> 329.3199 | G3: 3.8526487
A4: =MD!B63 -> 61 | B4: =MD!G63 -> 0.99433039 | C4: 325.56883 | D4: =B4*C4 -> 323.72299 | E4: =D4-1.96*G4 -> 316.15963 | F4: =D4+1.96*G4 -> 331.28634 | G4: 3.858856
A5: =MD!B64 -> 62 | B5: =MD!G64 -> 0.99686392 | C5: 326.75614 | D5: =B5*C5 -> 325.73141 | E5: =D5-1.96*G5 -> 318.15552 | F5: =D5+1.96*G5 -> 333.30731 | G5: 3.865253
A6: =MD!B65 -> 63 | B6: =MD!G65 -> 1.000381 | C6: 327.94346 | D6: =B6*C6 -> 328.0684 | E6: =D6-1.96*G6 -> 320.4796 | F6: =D6+1.96*G6 -> 335.65721 | G6: 3.8718389
A7: =MD!B66 -> 64 | B7: =MD!G66 -> 1.0020511 | C7: 329.13077 | D7: =B7*C7 -> 329.80586 | E7: =D7-1.96*G7 -> 322.20378 | F7: =D7+1.96*G7 -> 337.40794 | G7: 3.8786127
A8: =MD!B67 -> 65 | B8: =MD!G67 -> 1.0038353 | C8: 330.31808 | D8: =B8*C8 -> 331.58494 | E8: =D8-1.96*G8 -> 323.96922 | F8: =D8+1.96*G8 -> 339.20067 | G8: 3.8855734
A9: =MD!B68 -> 66 | B9: =MD!G68 -> 1.0064909 | C9: 331.50539 | D9: =B9*C9 -> 333.65716 | E9: =D9-1.96*G9 -> 326.02743 | F9: =D9+1.96*G9 -> 341.28689 | G9: 3.8927199
A10: =MD!B69 -> 67 | B10: =MD!G69 -> 1.0041768 | C10: 332.6927 | D10: =B10*C10 -> 334.0823 | E10: =D10-1.96*G10 -> 326.4382 | F10: =D10+1.96*G10 -> 341.7264 | G10: 3.9000514
A11: =MD!B70 -> 68 | B11: =MD!G70 -> 1.0027292 | C11: 333.88002 | D11: =B11*C11 -> 334.79123 | E11: =D11-1.96*G11 -> 327.1324 | F11: =D11+1.96*G11 -> 342.45007 | G11: 3.9075666
A12: =MD!B71 -> 69 | B12: =MD!G71 -> 1.0010332 | C12: 335.06733 | D12: =B12*C12 -> 335.41352 | E12: =D12-1.96*G12 -> 327.73961 | F12: =D12+1.96*G12 -> 343.08744 | G12: 3.9152646
A13: =MD!B72 -> 70 | B13: =MD!G72 -> 1.0000307 | C13: 336.25464 | D13: =B13*C13 -> 336.26497 | E13: =D13-1.96*G13 -> 328.57561 | F13: =D13+1.96*G13 -> 343.95433 | G13: 3.9231444
A14: =MD!B73 -> 71 | B14: =MD!G73 -> 0.99613217 | C14: 337.44195 | D14: =B14*C14 -> 336.13679 | E14: =D14-1.96*G14 -> 328.43162 | F14: =D14+1.96*G14 -> 343.84195 | G14: 3.9312047

Sheet AD
A1: Year | B1: t | C1: Y | D1: CMA | E1: Y-CMA | F1: SV_bar | G1: S | H1: DY | I1: DY^ | J1: Y^ | K1: C+I | L1: C | M1: I | N1: e^2 | O1: abs(e/Y) | P1: SUMMARY OUTPUT
C2: T+C+S+I | D2: T+C | E2: S+I | G2: SV_bar-(Sum(SV)/s) | H2: Y-S | I2: T | J2: T+S | K2: Y-Y^ | L2: Third(C+I) | M2: (C+I)-C | N2: (Y-Y^)2
A3: 1 | B3: 1 | C3: 257.971 | F3: =AVERAGE(E15,E27,E39,E51)-(SUM(AVERAGE(E15,27,39,51),AVERAGE(E16,28,40,52),AVERAGE(E17,29,41,53),AVERAGE(E18,30,42,54),AVERAGE(E19,31,43,55),AVERAGE(E20,32,44,56),AVERAGE(E9,21,33,45),AVERAGE(E10,22,34,46),AVERAGE(E11,23,35,47),AVERAGE(E12,24,36,48),AVERAGE(E13,25,37,49),AVERAGE(E14,26,38,50))/12) -> -30.365294 | G3: =F3 -> -30.365294 | H3: =C3-G3 -> 288.33629 | I3: =(Q$17+Q$18*B3) -> 253.13753 | J3: =I3+G3 -> 222.77224 | K3: =C3-J3 -> 35.198763 | N3: =(C3-J3)^2 -> 1238.953 | O3: =ABS(C3-J3)/C3 -> 0.13644465 | P3: Regression Statistics
B4: 2 | C4: 258.678 | F4: =AVERAGE(E16,E28,E40,E52)-(SUM(AVERAGE(E15,27,39,51),AVERAGE(E16,28,40,52),AVERAGE(E17,29,41,53),AVERAGE(E18,30,42,54),AVERAGE(E19,31,43,55),AVERAGE(E20,32,44,56),AVERAGE(E9,21,33,45),AVERAGE(E10,22,34,46),AVERAGE(E11,23,35,47),AVERAGE(E12,24,36,48),AVERAGE(E13,25,37,49),AVERAGE(E14,26,38,50))/12) -> -29.61968 | G4: =F4 -> -29.61968 | H4: =C4-G4 -> 288.29768 | I4: =(Q$17+Q$18*B4) -> 254.32491 | J4: =I4+G4 -> 224.70523 | K4: =C4-J4 -> 33.972769 | L4: =AVERAGE(K3:K5) -> 33.458484 | M4: =K4-L4 -> 0.51428472 | N4: =(C4-J4)^2 -> 1154.149 | O4: =ABS(C4-J4)/C4 -> 0.13133227 | P4: Multiple R | Q4: 0.98440754
B5: 3 | C5: 258.115 | F5: =AVERAGE(E17,E29,E41,E53)-(SUM(AVERAGE(E15,27,39,51),AVERAGE(E16,28,40,52),AVERAGE(E17,29,41,53),AVERAGE(E18,30,42,54),AVERAGE(E19,31,43,55),AVERAGE(E20,32,44,56),AVERAGE(E9,21,33,45),AVERAGE(E10,22,34,46),AVERAGE(E11,23,35,47),AVERAGE(E12,24,36,48),AVERAGE(E13,25,37,49),AVERAGE(E14,26,38,50))/12) -> -28.601211 | G5: =F5 -> -28.601211 | H5: =C5-G5 -> 286.71621 | I5: =(Q$17+Q$18*B5) -> 255.51229 | J5: =I5+G5 -> 226.91108 | K5: =C5-J5 -> 31.20392 | L5: =AVERAGE(K4:K6) -> 30.994968 | M5: =K5-L5 -> 0.20895139 | N5: =(C5-J5)^2 -> 973.68459 | O5: =ABS(C5-J5)/C5 -> 0.12089154 | P5: R Square | Q5: 0.9690582
B6: 4 | C6: 256.389 | F6: =AVERAGE(E18,E30,E42,E54)-(SUM(AVERAGE(E15,27,39,51),AVERAGE(E16,28,40,52),AVERAGE(E17,29,41,53),AVERAGE(E18,30,42,54),AVERAGE(E19,31,43,55),AVERAGE(E20,32,44,56),AVERAGE(E9,21,33,45),AVERAGE(E10,22,34,46),AVERAGE(E11,23,35,47),AVERAGE(E12,24,36,48),AVERAGE(E13,25,37,49),AVERAGE(E14,26,38,50))/12) -> -28.118888 | G6: =F6 -> -28.118888 | H6: =C6-G6 -> 284.50789 | I6: =(Q$17+Q$18*B6) -> 256.69967 | J6: =I6+G6 -> 228.58078 | K6: =C6-J6 -> 27.808216 | L6: =AVERAGE(K5:K7) -> 28.378727 | M6: =K6-L6 -> -0.57051042 | N6: =(C6-J6)^2 -> 773.29689 | O6: =ABS(C6-J6)/C6 -> 0.10846104 | P6: Adjusted R Square | Q6: 0.96852472
B7: 5 | C7: 256.394 | F7: =AVERAGE(E19,E31,E43,E55)-(SUM(AVERAGE(E15,27,39,51),AVERAGE(E16,28,40,52),AVERAGE(E17,29,41,53),AVERAGE(E18,30,42,54),AVERAGE(E19,31,43,55),AVERAGE(E20,32,44,56),AVERAGE(E9,21,33,45),AVERAGE(E10,22,34,46),AVERAGE(E11,23,35,47),AVERAGE(E12,24,36,48),AVERAGE(E13,25,37,49),AVERAGE(E14,26,38,50))/12) -> -27.617096 | G7: =F7 -> -27.617096 | H7: =C7-G7 -> 284.0111 | I7: =(Q$17+Q$18*B7) -> 257.88705 | J7: =I7+G7 -> 230.26996 | K7: =C7-J7 -> 26.124044 | L7: =AVERAGE(K6:K8) -> 26.506958 | M7: =K7-L7 -> -0.38291319 | N7: =(C7-J7)^2 -> 682.46569 | O7: =ABS(C7-J7)/C7 -> 0.10189023 | P7: Standard Error | Q7: 3.7372283
B8: 6 | C8: 257.797 | F8: =AVERAGE(E20,E32,E44,E56)-(SUM(AVERAGE(E15,27,39,51),AVERAGE(E16,28,40,52),AVERAGE(E17,29,41,53),AVERAGE(E18,30,42,54),AVERAGE(E19,31,43,55),AVERAGE(E20,32,44,56),AVERAGE(E9,21,33,45),AVERAGE(E10,22,34,46),AVERAGE(E11,23,35,47),AVERAGE(E12,24,36,48),AVERAGE(E13,25,37,49),AVERAGE(E14,26,38,50))/12) -> -26.866044 | G8: =F8 -> -26.866044 | H8: =C8-G8 -> 284.66304 | I8: =(Q$17+Q$18*B8) -> 259.07443 | J8: =I8+G8 -> 232.20839 | K8: =C8-J8 -> 25.588612 | L8: =AVERAGE(K7:K9) -> 26.034411 | M8: =K8-L8 -> -0.44579861 | N8: =(C8-J8)^2 -> 654.77706 | O8: =ABS(C8-J8)/C8 -> 0.099258765 | P8: Observations | Q8: 60
B9: 7 | C9: 259.101 | D9: =(0.5*C3+C4+C5+C6+C7+C8+C9+C10+C11+C12+C13+C14+0.5*C15)/12 -> 258.96163 | E9: =C9-D9 -> 0.139375 | F9: =AVERAGE(E9,E21,E33,E45)-(SUM(AVERAGE(E15,27,39,51),AVERAGE(E16,28,40,52),AVERAGE(E17,29,41,53),AVERAGE(E18,30,42,54),AVERAGE(E19,31,43,55),AVERAGE(E20,32,44,56),AVERAGE(E9,21,33,45),AVERAGE(E10,22,34,46),AVERAGE(E11,23,35,47),AVERAGE(E12,24,36,48),AVERAGE(E13,25,37,49),AVERAGE(E14,26,38,50))/12) -> -27.551388 | G9: =F9 -> -27.551388 | H9: =C9-G9 -> 286.65239 | I9: =(Q$17+Q$18*B9) -> 260.26181 | J9: =I9+G9 -> 232.71042 | K9: =C9-J9 -> 26.390575 | L9: =AVERAGE(K8:K10) -> 26.136704 | M9: =K9-L9 -> 0.25387153 | N9: =(C9-J9)^2 -> 696.46247 | O9: =ABS(C9-J9)/C9 -> 0.10185439
B10: 8 | C10: 259.918 | D10: =(0.5*C4+C5+C6+C7+C8+C9+C10+C11+C12+C13+C14+C15+0.5*C16)/12 -> 259.29275 | E10: =C10-D10 -> 0.62525 | F10: =AVERAGE(E10,E22,E34,E46)-(SUM(AVERAGE(E15,27,39,51),AVERAGE(E16,28,40,52),AVERAGE(E17,29,41,53),AVERAGE(E18,30,42,54),AVERAGE(E19,31,43,55),AVERAGE(E20,32,44,56),AVERAGE(E9,21,33,45),AVERAGE(E10,22,34,46),AVERAGE(E11,23,35,47),AVERAGE(E12,24,36,48),AVERAGE(E13,25,37,49),AVERAGE(E14,26,38,50))/12) -> -27.962117 | G10: =F10 -> -27.962117 | H10: =C10-G10 -> 287.88012 | I10: =(Q$17+Q$18*B10) -> 261.44919 | J10: =I10+G10 -> 233.48708 | K10: =C10-J10 -> 26.430924 | L10: =AVERAGE(K9:K11) -> 26.301185 | M10: =K10-L10 -> 0.12973958 | N10: =(C10-J10)^2 -> 698.59376 | O10: =ABS(C10-J10)/C10 -> 0.10168947 | P10: ANOVA
B11: 9 | C11: 260.28 | D11: =(0.5*C5+C6+C7+C8+C9+C10+C11+C12+C13+C14+C15+C16+0.5*C17)/12 -> 259.75517 | E11: =C11-D11 -> 0.52483333 | F11: =AVERAGE(E11,E23,E35,E47)-(SUM(AVERAGE(E15,27,39,51),AVERAGE(E16,28,40,52),AVERAGE(E17,29,41,53),AVERAGE(E18,30,42,54),AVERAGE(E19,31,43,55),AVERAGE(E20,32,44,56),AVERAGE(E9,21,33,45),AVERAGE(E10,22,34,46),AVERAGE(E11,23,35,47),AVERAGE(E12,24,36,48),AVERAGE(E13,25,37,49),AVERAGE(E14,26,38,50))/12) -> -28.438628 | G11: =F11 -> -28.438628 | H11: =C11-G11 -> 288.71863 | I11: =(Q$17+Q$18*B11) -> 262.63657 | J11: =I11+G11 -> 234.19795 | K11: =C11-J11 -> 26.082054 | L11: =AVERAGE(K10:K12) -> 25.935856 | M11: =K11-L11 -> 0.14619792 | N11: =(C11-J11)^2 -> 680.27356 | O11: =ABS(C11-J11)/C11 -> 0.10020768 | Q11: df | R11: SS | S11: MS | T11: F | U11: Significance F
B12: 10 | C12: 260.388 | D12: =(0.5*C6+C7+C8+C9+C10+C11+C12+C13+C14+C15+C16+C17+0.5*C18)/12 -> 260.48129 | E12: =C12-D12 -> -0.093291667 | F12: =AVERAGE(E12,E24,E36,E48)-(SUM(AVERAGE(E15,27,39,51),AVERAGE(E16,28,40,52),AVERAGE(E17,29,41,53),AVERAGE(E18,30,42,54),AVERAGE(E19,31,43,55),AVERAGE(E20,32,44,56),AVERAGE(E9,21,33,45),AVERAGE(E10,22,34,46),AVERAGE(E11,23,35,47),AVERAGE(E12,24,36,48),AVERAGE(E13,25,37,49),AVERAGE(E14,26,38,50))/12) -> -28.730544 | G12: =F12 -> -28.730544 | H12: =C12-G12 -> 289.11854 | I12: =(Q$17+Q$18*B12) -> 263.82395 | J12: =I12+G12 -> 235.09341 | K12: =C12-J12 -> 25.294591 | L12: =AVERAGE(K11:K13) -> 25.483764 | M12: =K12-L12 -> -0.18917361 | N12: =(C12-J12)^2 -> 639.81632 | O12: =ABS(C12-J12)/C12 -> 0.097141922 | P12: Regression | Q12: 1 | R12: 25370.647 | S12: 25370.647 | T12: 1816.4869 | U12: 1.7814356e-45
B13: 11 | C13: 260.229 | D13: =(0.5*C7+C8+C9+C10+C11+C12+C13+C14+C15+C16+C17+C18+0.5*C19)/12 -> 261.45904 | E13: =C13-D13 -> -1.2300417 | F13: =AVERAGE(E13,E25,E37,E49)-(SUM(AVERAGE(E15,27,39,51),AVERAGE(E16,28,40,52),AVERAGE(E17,29,41,53),AVERAGE(E18,30,42,54),AVERAGE(E19,31,43,55),AVERAGE(E20,32,44,56),AVERAGE(E9,21,33,45),AVERAGE(E10,22,34,46),AVERAGE(E11,23,35,47),AVERAGE(E12,24,36,48),AVERAGE(E13,25,37,49),AVERAGE(E14,26,38,50))/12) -> -29.856982 | G13: =F13 -> -29.856982 | H13: =C13-G13 -> 290.08598 | I13: =(Q$17+Q$18*B13) -> 265.01133 | J13: =I13+G13 -> 235.15435 | K13: =C13-J13 -> 25.074648 | L13: =AVERAGE(K12:K14) -> 25.239853 | M13: =K13-L13 -> -0.16520486 | N13: =(C13-J13)^2 -> 628.73797 | O13: =ABS(C13-J13)/C13 -> 0.096356086 | P13: Residual | Q13: 58 | R13: 810.07877 | S13: 13.966875
B14: 12 | C14: 260.474 | D14: =(0.5*C8+C9+C10+C11+C12+C13+C14+C15+C16+C17+C18+C19+0.5*C20)/12 -> 262.57154 | E14: =C14-D14 -> -2.0975417 | F14: =AVERAGE(E14,E26,E38,E50)-(SUM(AVERAGE(E15,27,39,51),AVERAGE(E16,28,40,52),AVERAGE(E17,29,41,53),AVERAGE(E18,30,42,54),AVERAGE(E19,31,43,55),AVERAGE(E20,32,44,56),AVERAGE(E9,21,33,45),AVERAGE(E10,22,34,46),AVERAGE(E11,23,35,47),AVERAGE(E12,24,36,48),AVERAGE(E13,25,37,49),AVERAGE(E14,26,38,50))/12) -> -31.075034 | G14: =F14 -> -31.075034 | H14: =C14-G14 -> 291.54903 | I14: =(Q$17+Q$18*B14) -> 266.19871 | J14: =I14+G14 -> 235.12368 | K14: =C14-J14 -> 25.35032 | L14: =AVERAGE(K13:K15) -> 24.995389 | M14: =K14-L14 -> 0.35493056 | N14: =(C14-J14)^2 -> 642.63871 | O14: =ABS(C14-J14)/C14 -> 0.097323801 | P14: Total | Q14: 59 | R14: 26180.726
A15: 2 | B15: 13 | C15: 261.582 | D15: =(0.5*C9+C10+C11+C12+C13+C14+C15+C16+C17+C18+C19+C20+0.5*C21)/12 -> 263.72992 | E15: =C15-D15 -> -2.1479167 | F15: =SUM(F3:F14) -> -344.80291 | G15: =G3 -> -30.365294 | H15: =C15-G15 -> 291.94729 | I15: =(Q$17+Q$18*B15) -> 267.38609 | J15: =I15+G15 -> 237.0208 | K15: =C15-J15 -> 24.5612 | L15: =AVERAGE(K14:K16) -> 24.657241 | M15: =K15-L15 -> -0.096041667 | N15: =(C15-J15)^2 -> 603.25253 | O15: =ABS(C15-J15)/C15 -> 0.093894839
B16: 14 | C16: 263.014 | D16: =(0.5*C10+C11+C12+C13+C14+C15+C16+C17+C18+C19+C20+C21+0.5*C22)/12 -> 264.87788 | E16: =C16-D16 -> -1.863875 | G16: =G4 -> -29.61968 | H16: =C16-G16 -> 292.63368 | I16: =(Q$17+Q$18*B16) -> 268.57347 | J16: =I16+G16 -> 238.9538 | K16: =C16-J16 -> 24.060205 | L16: =AVERAGE(K15:K17) -> 24.11292 | M16: =K16-L16 -> -0.052715278 | N16: =(C16-J16)^2 -> 578.89346 | O16: =ABS(C16-J16)/C16 -> 0.091478799 | Q16: Coefficients | R16: Standard Error | S16: t Stat | T16: P-value | U16: Lower 95% | V16: Upper 95% | W16: Lower 95.0% | X16: Upper 95.0%
B17: 15 | C17: 264.877 | D17: =(0.5*C11+C12+C13+C14+C15+C16+C17+C18+C19+C20+C21+C22+0.5*C23)/12 -> 266.03117 | E17: =C17-D17 -> -1.1541667 | G17: =G5 -> -28.601211 | H17: =C17-G17 -> 293.47821 | I17: =(Q$17+Q$18*B17) -> 269.76086 | J17: =I17+G17 -> 241.15964 | K17: =C17-J17 -> 23.717356 | L17: =AVERAGE(K16:K18) -> 24.000738 | M17: =K17-L17 -> -0.28338194 | N17: =(C17-J17)^2 -> 562.51297 | O17: =ABS(C17-J17)/C17 -> 0.089541016 | P17: Intercept | Q17: 251.95015 | R17: 0.9771375 | S17: 257.84513 | T17: 1.9415472e-90 | U17: 249.9942 | V17: 253.9061 | W17: 249.9942 | X17: 253.9061
B18: 16 | C18: 267.054 | D18: =(0.5*C12+C13+C14+C15+C16+C17+C18+C19+C20+C21+C22+C23+0.5*C24)/12 -> 267.29079 | E18: =C18-D18 -> -0.23679167 | G18: =G6 -> -28.118888 | H18: =C18-G18 -> 295.17289 | I18: =(Q$17+Q$18*B18) -> 270.94824 | J18: =I18+G18 -> 242.82935 | K18: =C18-J18 -> 24.224653 | L18: =AVERAGE(K17:K19) -> 24.206163 | M18: =K18-L18 -> 0.018489583 | N18: =(C18-J18)^2 -> 586.83379 | O18: =ABS(C18-J18)/C18 -> 0.09071069 | P18: X Variable 1 | Q18: 1.1873803 | R18: 0.027859525 | S18: 42.620264 | T18: 1.7814356e-45 | U18: 1.1316134 | V18: 1.2431472 | W18: 1.1316134 | X18: 1.2431472
B19: 17 | C19: 269.195 | D19: =(0.5*C13+C14+C15+C16+C17+C18+C19+C20+C21+C22+C23+C24+0.5*C25)/12 -> 268.70413 | E19: =C19-D19 -> 0.490875 | G19: =G7 -> -27.617096 | H19: =C19-G19 -> 296.8121 | I19: =(Q$17+Q$18*B19) -> 272.13562 | J19: =I19+G19 -> 244.51852 | K19: =C19-J19 -> 24.676481 | L19: =AVERAGE(K18:K20) -> 24.713394 | M19: =K19-L19 -> -0.036913194 | N19: =(C19-J19)^2 -> 608.92869 | O19: =ABS(C19-J19)/C19 -> 0.091667678
B20: 18 | C20: 271.696 | D20: =(0.5*C14+C15+C16+C17+C18+C19+C20+C21+C22+C23+C24+C25+0.5*C26)/12 -> 270.20608 | E20: =C20-D20 -> 1.4899167 | G20: =G8 -> -26.866044 | H20: =C20-G20 -> 298.56204 | I20: =(Q$17+Q$18*B20) -> 273.323 | J20: =I20+G20 -> 246.45695 | K20: =C20-J20 -> 25.239048 | L20: =AVERAGE(K19:K21) -> 25.319847 | M20: =K20-L20 -> -0.080798611 | N20: =(C20-J20)^2 -> 637.00955 | O20: =ABS(C20-J20)/C20 -> 0.092894442
B21: 19 | C21: 273.003 | D21: =(0.5*C15+C16+C17+C18+C19+C20+C21+C22+C23+C24+C25+C26+0.5*C27)/12 -> 271.785 | E21: =C21-D21 -> 1.218 | G21: =G9 -> -27.551388 | H21: =C21-G21 -> 300.55439 | I21: =(Q$17+Q$18*B21) -> 274.51038 | J21: =I21+G21 -> 246.95899 | K21: =C21-J21 -> 26.044012 | L21: =AVERAGE(K20:K22) -> 25.704807 | M21: =K21-L21 -> 0.33920486 | N21: =(C21-J21)^2 -> 678.29054 | O21: =ABS(C21-J21)/C21 -> 0.095398262
B22: 20 | C22: 273.567 | D22: =(0.5*C16+C17+C18+C19+C20+C21+C22+C23+C24+C25+C26+C27+0.5*C28)/12 -> 273.46283 | E22: =C22-D22 -> 0.10416667 | G22: =G10 -> -27.962117 | H22: =C22-G22 -> 301.52912 | I22: =(Q$17+Q$18*B22) -> 275.69776 | J22: =I22+G22 -> 247.73564 | K22: =C22-J22 -> 25.83136 | L22: =AVERAGE(K21:K23) -> 25.912954 | M22: =K22-L22 -> -0.08159375 | N22: =(C22-J22)^2 -> 667.25918 | O22: =ABS(C22-J22)/C22 -> 0.094424256
B23: 21 | C23: 274.31 | D23: =(0.5*C17+C18+C19+C20+C21+C22+C23+C24+C25+C26+C27+C28+0.5*C29)/12 -> 275.26821 | E23: =C23-D23 -> -0.95820833 | G23: =G11 -> -28.438628 | H23: =C23-G23 -> 302.74863 | I23: =(Q$17+Q$18*B23) -> 276.88514 | J23: =I23+G23 -> 248.44651 | K23: =C23-J23 -> 25.863491 | L23: =AVERAGE(K22:K24) -> 26.313959 | M23: =K23-L23 -> -0.45046875 | N23: =(C23-J23)^2 -> 668.92014 | O23: =ABS(C23-J23)/C23 -> 0.094285628
B24: 22 | C24: 276.589 | D24: =(0.5*C18+C19+C20+C21+C22+C23+C24+C25+C26+C27+C28+C29+0.5*C30)/12 -> 277.12996 | E24: =C24-D24 -> -0.54095833 | G24: =G12 -> -28.730544 | H24: =C24-G24 -> 305.31954 | I24: =(Q$17+Q$18*B24) -> 278.07252 | J24: =I24+G24 -> 249.34197 | K24: =C24-J24 -> 27.247027 | L24: =AVERAGE(K23:K25) -> 27.218534 | M24: =K24-L24 -> 0.028493056 | N24: =(C24-J24)^2 -> 742.40048 | O24: =ABS(C24-J24)/C24 -> 0.098510884
B25: 23 | C25: 277.948 | D25: =(0.5*C19+C20+C21+C22+C23+C24+C25+C26+C27+C28+C29+C30+0.5*C31)/12 -> 279.01146 | E25: =C25-D25 -> -1.0634583 | G25: =G13 -> -29.856982 | H25: =C25-G25 -> 307.80498 | I25: =(Q$17+Q$18*B25) -> 279.2599 | J25: =I25+G25 -> 249.40292 | K25: =C25-J25 -> 28.545084 | L25: =AVERAGE(K24:K26) -> 28.407289 | M25: =K25-L25 -> 0.13779514 | N25: =(C25-J25)^2 -> 814.82183 | O25: =ABS(C25-J25)/C25 -> 0.10269937
B26: 24 | C26: 278.802 | D26: =(0.5*C20+C21+C22+C23+C24+C25+C26+C27+C28+C29+C30+C31+0.5*C32)/12 -> 280.99962 | E26: =C26-D26 -> -2.197625 | G26: =G14 -> -31.075034 | H26: =C26-G26 -> 309.87703 | I26: =(Q$17+Q$18*B26) -> 280.44728 | J26: =I26+G26 -> 249.37224 | K26: =C26-J26 -> 29.429756 | L26: =AVERAGE(K25:K27) -> 29.284492 | M26: =K26-L26 -> 0.14526389 | N26: =(C26-J26)^2 -> 866.11053 | O26: =ABS(C26-J26)/C26 -> 0.10555791
A27: 3 | B27: 25 | C27: 281.148 | D27: =(0.5*C21+C22+C23+C24+C25+C26+C27+C28+C29+C30+C31+C32+0.5*C33)/12 -> 282.99496 | E27: =C27-D27 -> -1.8469583 | G27: =G3 -> -30.365294 | H27: =C27-G27 -> 311.51329 | I27: =(Q$17+Q$18*B27) -> 281.63466 | J27: =I27+G27 -> 251.26936 | K27: =C27-J27 -> 29.878636 | L27: =AVERAGE(K26:K28) -> 29.940678 | M27: =K27-L27 -> -0.062041667 | N27: =(C27-J27)^2 -> 892.73289 | O27: =ABS(C27-J27)/C27 -> 0.10627369
B28: 26 | C28: 283.716 | D28: =(0.5*C22+C23+C24+C25+C26+C27+C28+C29+C30+C31+C32+C33+0.5*C34)/12 -> 284.9065 | E28: =C28-D28 -> -1.1905 | G28: =G4 -> -29.61968 | H28: =C28-G28 -> 313.33568 | I28: =(Q$17+Q$18*B28) -> 282.82204 | J28: =I28+G28 -> 253.20236 | K28: =C28-J28 -> 30.513641 | L28: =AVERAGE(K27:K29) -> 30.829356 | M28: =K28-L28 -> -0.31571528 | N28: =(C28-J28)^2 -> 931.08229 | O28: =ABS(C28-J28)/C28 -> 0.10754995
B29: 27 | C29: 287.504 | D29: =(0.5*C23+C24+C25+C26+C27+C28+C29+C30+C31+C32+C33+C34+0.5*C35)/12 -> 286.78575 | E29: =C29-D29 -> 0.71825 | G29: =G5 -> -28.601211 | H29: =C29-G29 -> 316.10521 | I29: =(Q$17+Q$18*B29) -> 284.00942 | J29: =I29+G29 -> 255.40821 | K29: =C29-J29 -> 32.095792 | L29: =AVERAGE(K28:K30) -> 31.546841 | M29: =K29-L29 -> 0.54895139 | N29: =(C29-J29)^2 -> 1030.1399 | O29: =ABS(C29-J29)/C29 -> 0.11163598
B30: 28 | C30: 289.109 | D30: =(0.5*C24+C25+C26+C27+C28+C29+C30+C31+C32+C33+C34+C35+0.5*C36)/12 -> 288.61579 | E30: =C30-D30 -> 0.49320833 | G30: =G6 -> -28.118888 | H30: =C30-G30 -> 317.22789 | I30: =(Q$17+Q$18*B30) -> 285.1968 | J30: =I30+G30 -> 257.07791 | K30: =C30-J30 -> 32.031089 | L30: =AVERAGE(K29:K31) -> 32.551933 | M30: =K30-L30 -> -0.52084375 | N30: =(C30-J30)^2 -> 1025.9906 | O30: =ABS(C30-J30)/C30 -> 0.11079243
B31: 29 | C31: 292.296 | D31: =(0.5*C25+C26+C27+C28+C29+C30+C31+C32+C33+C34+C35+C36+0.5*C37)/12 -> 290.33188 | E31: =C31-D31 -> 1.964125 | G31: =G7 -> -27.617096 | H31: =C31-G31 -> 319.9131 | I31: =(Q$17+Q$18*B31) -> 286.38418 | J31: =I31+G31 -> 258.76708 | K31: =C31-J31 -> 33.528917 | L31: =AVERAGE(K30:K32) -> 33.72183 | M31: =K31-L31 -> -0.19291319 | N31: =(C31-J31)^2 -> 1124.1883 | O31: =ABS(C31-J31)/C31 -> 0.11470878
B32: 30 | C32: 296.311 | D32: =(0.5*C26+C27+C28+C29+C30+C31+C32+C33+C34+C35+C36+C37+0.5*C38)/12 -> 291.90512 | E32: =C32-D32 -> 4.405875 | G32: =G8 -> -26.866044 | H32: =C32-G32 -> 323.17704 | I32: =(Q$17+Q$18*B32) -> 287.57156 | J32: =I32+G32 -> 260.70552 | K32: =C32-J32 -> 35.605484 | L32: =AVERAGE(K31:K33) -> 34.734283 | M32: =K32-L32 -> 0.87120139 | N32: =(C32-J32)^2 -> 1267.7505 | O32: =ABS(C32-J32)/C32 -> 0.12016255
B33: 31 | C33: 296.276 | D33: =(0.5*C27+C28+C29+C30+C31+C32+C33+C34+C35+C36+C37+C38+0.5*C39)/12 -> 293.40583 | E33: =C33-D33 -> 2.8701667 | G33: =G9 -> -27.551388 | H33: =C33-G33 -> 323.82739 | I33: =(Q$17+Q$18*B33) -> 288.75894 | J33: =I33+G33 -> 261.20755 | K33: =C33-J33 -> 35.068448 | L33: =AVERAGE(K32:K34) -> 34.953576 | M33: =K33-L33 -> 0.11487153 | N33: =(C33-J33)^2 -> 1229.796 | O33: =ABS(C33-J33)/C33 -> 0.11836412
B34: 32 | C34: 296.171 | D34: =(0.5*C28+C29+C30+C31+C32+C33+C34+C35+C36+C37+C38+C39+0.5*C40)/12 -> 294.87025 | E34: =C34-D34 -> 1.30075 | G34: =G10 -> -27.962117 | H34: =C34-G34 -> 324.13312 | I34: =(Q$17+Q$18*B34) -> 289.94632 | J34: =I34+G34 -> 261.9842 | K34: =C34-J34 -> 34.186797 | L34: =AVERAGE(K33:K35) -> 34.456057 | M34: =K34-L34 -> -0.26926042 | N34: =(C34-J34)^2 -> 1168.7371 | O34: =ABS(C34-J34)/C34 -> 0.11542925
B35: 33 | C35: 296.808 | D35: =(0.5*C29+C30+C31+C32+C33+C34+C35+C36+C37+C38+C39+C40+0.5*C41)/12 -> 296.18092 | E35: =C35-D35 -> 0.62708333 | G35: =G11 -> -28.438628 | H35: =C35-G35 -> 325.24663 | I35: =(Q$17+Q$18*B35) -> 291.1337 | J35: =I35+G35 -> 262.69507 | K35: =C35-J35 -> 34.112927 | L35: =AVERAGE(K34:K36) -> 34.240396 | M35: =K35-L35 -> -0.12746875 | N35: =(C35-J35)^2 -> 1163.6918 | O35: =ABS(C35-J35)/C35 -> 0.11493264
B36: 34 | C36: 298.012 | D36: =(0.5*C30+C31+C32+C33+C34+C35+C36+C37+C38+C39+C40+C41+0.5*C42)/12 -> 297.372 | E36: =C36-D36 -> 0.64 | G36: =G12 -> -28.730544 | H36: =C36-G36 -> 326.74254 | I36: =(Q$17+Q$18*B36) -> 292.32108 | J36: =I36+G36 -> 263.59054 | K36: =C36-J36 -> 34.421463 | L36: =AVERAGE(K35:K37) -> 34.19797 | M36: =K36-L36 -> 0.22349306 | N36: =(C36-J36)^2 -> 1184.8371 | O36: =ABS(C36-J36)/C36 -> 0.11550361
B37: 35 | C37: 297.711 | D37: =(0.5*C31+C32+C33+C34+C35+C36+C37+C38+C39+C40+C41+C42+0.5*C43)/12 -> 298.45887 | E37: =C37-D37 -> -0.747875 | G37: =G13 -> -29.856982 | H37: =C37-G37 -> 327.56798 | I37: =(Q$17+Q$18*B37) -> 293.50846 | J37: =I37+G37 -> 263.65148 | K37: =C37-J37 -> 34.05952 | L37: =AVERAGE(K36:K38) -> 33.885725 | M37: =K37-L37 -> 0.17379514 | N37: =(C37-J37)^2 -> 1160.0509 | O37: =ABS(C37-J37)/C37 -> 0.11440464
B38: 36 | C38: 296.797 | D38: =(0.5*C32+C33+C34+C35+C36+C37+C38+C39+C40+C41+C42+C43+0.5*C44)/12 -> 299.31842 | E38: =C38-D38 -> -2.5214167 | G38: =G14 -> -31.075034 | H38: =C38-G38 -> 327.87203 | I38: =(Q$17+Q$18*B38) -> 294.69584 | J38: =I38+G38 -> 263.62081 | K38: =C38-J38 -> 33.176192 | L38: =AVERAGE(K37:K39) -> 33.629262 | M38: =K38-L38 -> -0.45306944 | N38: =(C38-J38)^2 -> 1100.6597 | O38: =ABS(C38-J38)/C38 -> 0.11178075
A39: 4 | B39: 37 | C39: 299.17 | D39: =(0.5*C33+C34+C35+C36+C37+C38+C39+C40+C41+C42+C43+C44+0.5*C45)/12 -> 300.07729 | E39: =C39-D39 -> -0.90729167 | G39: =G3 -> -30.365294 | H39: =C39-G39 -> 329.53529 | I39: =(Q$17+Q$18*B39) -> 295.88322 | J39: =I39+G39 -> 265.51793 | K39: =C39-J39 -> 33.652072 | L39: =AVERAGE(K38:K40) -> 33.405781 | M39: =K39-L39 -> 0.24629167 | N39: =(C39-J39)^2 -> 1132.462 | O39: =ABS(C39-J39)/C39 -> 0.11248478
B40: 38 | C40: 300.84 | D40: =(0.5*C34+C35+C36+C37+C38+C39+C40+C41+C42+C43+C44+C45+0.5*C46)/12 -> 300.92187 | E40: =C40-D40 -> -0.081875 | G40: =G4 -> -29.61968 | H40: =C40-G40 -> 330.45968 | I40: =(Q$17+Q$18*B40) -> 297.0706 | J40: =I40+G40 -> 267.45092 | K40: =C40-J40 -> 33.389077 | L40: =AVERAGE(K39:K41) -> 33.073459 | M40: =K40-L40 -> 0.31561806 | N40: =(C40-J40)^2 -> 1114.8305 | O40: =ABS(C40-J40)/C40 -> 0.11098616
...

Sheet ADF
A1: t | B1: S | C1: T | D1: Y^ | E1: Y^L | F1: Y^U | G1: sT
E2: Y^-(Za/2*sT) | F2: Y^+(Za/2*sT)
A3: =AD!B62 -> 60 | B3: =AD!G62 -> -31.075034 | C3: 324.38035 | D3: =B3+C3 -> 293.30532 | E3: =D3-1.96*G3 -> 285.73411 | F3: =D3+1.96*G3 -> 300.87652 | G3: 3.8628582
A4: =AD!B63 -> 61 | B4: =AD!G63 -> -30.365294 | C4: 325.56773 | D4: =B4+C4 -> 295.20244 | E4: =D4-1.96*G4 -> 287.61904 | F4: =D4+1.96*G4 -> 302.78584 | G4: 3.8690819
A5: =AD!B64 -> 62 | B5: =AD!G64 -> -29.61968 | C5: 326.75511 | D5: =B5+C5 -> 297.13543 | E5: =D5-1.96*G5 -> 289.53946 | F5: =D5+1.96*G5 -> 304.7314 | G5: 3.8754959
A6: =AD!B65 -> 63 | B6: =AD!G65 -> -28.601211 | C6: 327.94249 | D6: =B6+C6 -> 299.34128 | E6: =D6-1.96*G6 -> 291.73237 | F6: =D6+1.96*G6 -> 306.95019 | G6: 3.8820992
A7: =AD!B66 -> 64 | B7: =AD!G66 -> -28.118888 | C7: 329.12987 | D7: =B7+C7 -> 301.01098 | E7: =D7-1.96*G7 -> 293.38876 | F7: =D7+1.96*G7 -> 308.63321 | G7: 3.888891
A8: =AD!B67 -> 65 | B8: =AD!G67 -> -27.617096 | C8: 330.31725 | D8: =B8+C8 -> 302.70015 | E8: =D8-1.96*G8 -> 295.06425 | F8: =D8+1.96*G8 -> 310.33606 | G8: 3.8958701
A9: =AD!B68 -> 66 | B9: =AD!G68 -> -26.866044 | C9: 331.50463 | D9: =B9+C9 -> 304.63859 | E9: =D9-1.96*G9 -> 296.98864 | F9: =D9+1.96*G9 -> 312.28854 | G9: 3.9030356
A10: =AD!B69 -> 67 | B10: =AD!G69 -> -27.551388 | C10: 332.69201 | D10: =B10+C10 -> 305.14062 | E10: =D10-1.96*G10 -> 297.47627 | F10: =D10+1.96*G10 -> 312.80498 | G10: 3.9103864
A11: =AD!B70 -> 68 | B11: =AD!G70 -> -27.962117 | C11: 333.87939 | D11: =B11+C11 -> 305.91727 | E11: =D11-1.96*G11 -> 298.23815 | F11: =D11+1.96*G11 -> 313.5964 | G11: 3.9179216
A12: =AD!B71 -> 69 | B12: =AD!G71 -> -28.438628 | C12: 335.06677 | D12: =B12+C12 -> 306.62814 | E12: =D12-1.96*G12 -> 298.93389 | F12: =D12+1.96*G12 -> 314.3224 | G12: 3.92564
A13: =AD!B72 -> 70 | B13: =AD!G72 -> -28.730544 | C13: 336.25415 | D13: =B13+C13 -> 307.52361 | E13: =D13-1.96*G13 -> 299.81387 | F13: =D13+1.96*G13 -> 315.23335 | G13: 3.9335406
A14: =AD!B73 -> 71 | B14: =AD!G73 -> -29.856982 | C14: 337.44153 | D14: =B14+C14 -> 307.58455 | E14: =D14-1.96*G14 -> 299.85897 | F14: =D14+1.96*G14 -> 315.31013 | G14: 3.9416223
